<?xml version="1.0" ?>
<!-- =================================================================================== -->
<!-- |    This document was autogenerated by xacro from dual_man.xacro                 | -->
<!-- |    EDITING THIS FILE BY HAND IS NOT RECOMMENDED                                 | -->
<!-- =================================================================================== -->
<!--Generates a urdf from the macro in sia5_macro.xacro -->
<robot name="dual_manipulator" xmlns:xacro="http://ros.org/wiki/xacro">
  <material name="purple">
    <color rgba="0.6 0 0.2 2"/>
  </material>
  <link name="base_link">
    <visual>
      <geometry>
        <box size="1 2 0.2"/>
      </geometry>
      <material name="purple"/>
    </visual>
  </link>
  <!--degrees to radians-->
  <link name="1base_link">
    <visual>
      <origin rpy="0 0 0" xyz="0 0 0"/>
      <geometry>
        <mesh filename="package://motoman_sia5d_support/meshes/sia5d/visual/base.dae"/>
      </geometry>
    </visual>
    <collision>
      <origin rpy="0 0 0" xyz="0 0 0"/>
      <geometry>
        <mesh filename="package://motoman_sia5d_support/meshes/sia5d/collision/base.dae"/>
      </geometry>
    </collision>
  </link>
  <link name="1link_s">
    <visual>
      <origin rpy="0 0 0" xyz="0 0 0"/>
      <geometry>
        <mesh filename="package://motoman_sia5d_support/meshes/sia5d/visual/link_s.dae"/>
      </geometry>
    </visual>
    <collision>
      <origin rpy="0 0 0" xyz="0 0 0"/>
      <geometry>
        <mesh filename="package://motoman_sia5d_support/meshes/sia5d/collision/link_s.dae"/>
      </geometry>
    </collision>
  </link>
  <joint name="1joint_s" type="revolute">
    <origin rpy="0 0 0" xyz="0 0 0.31"/>
    <!--r=${90*deg}-->
    <parent link="1base_link"/>
    <child link="1link_s"/>
    <axis xyz="0 0 1"/>
    <limit effort="0" lower="-3.14159274" upper="3.14159274" velocity="3.4906586"/>
  </joint>
  <link name="1link_l">
    <visual>
      <origin rpy="0 0 0" xyz="0 0 0"/>
      <geometry>
        <mesh filename="package://motoman_sia5d_support/meshes/sia5d/visual/link_l.dae"/>
      </geometry>
    </visual>
    <collision>
      <origin rpy="0 0 0" xyz="0 0 0"/>
      <geometry>
        <mesh filename="package://motoman_sia5d_support/meshes/sia5d/collision/link_l.dae"/>
      </geometry>
    </collision>
  </link>
  <joint name="1joint_l" type="revolute">
    <origin rpy="0 0 0" xyz="0 0 0"/>
    <parent link="1link_s"/>
    <child link="1link_l"/>
    <axis xyz="0 1 0"/>
    <limit effort="0" lower="-1.91986223" upper="1.91986223" velocity="3.4906586"/>
  </joint>
  <link name="1link_e">
    <visual>
      <origin rpy="0 0 0" xyz="0 0 0"/>
      <geometry>
        <mesh filename="package://motoman_sia5d_support/meshes/sia5d/visual/link_e.dae"/>
      </geometry>
    </visual>
    <collision>
      <origin rpy="0 0 0" xyz="0 0 0"/>
      <geometry>
        <mesh filename="package://motoman_sia5d_support/meshes/sia5d/collision/link_e.dae"/>
      </geometry>
    </collision>
  </link>
  <joint name="1joint_e" type="revolute">
    <origin rpy="0 0 0" xyz="0 0 0.27"/>
    <parent link="1link_l"/>
    <child link="1link_e"/>
    <axis xyz="0 0 1"/>
    <limit effort="0" lower="-2.96705981" upper="2.96705981" velocity="3.4906586"/>
  </joint>
  <link name="1link_u">
    <visual>
      <origin rpy="0 0 0" xyz="0 0 0"/>
      <geometry>
        <mesh filename="package://motoman_sia5d_support/meshes/sia5d/visual/link_u.dae"/>
      </geometry>
    </visual>
    <collision>
      <origin rpy="0 0 0" xyz="0 0 0"/>
      <geometry>
        <mesh filename="package://motoman_sia5d_support/meshes/sia5d/collision/link_u.dae"/>
      </geometry>
    </collision>
  </link>
  <joint name="1joint_u" type="revolute">
    <origin rpy="0 0 0" xyz="0.085 0 0"/>
    <parent link="1link_e"/>
    <child link="1link_u"/>
    <axis xyz="0 -1 0"/>
    <limit effort="0" lower="-1.57079637" upper="2.007128695" velocity="3.4906586"/>
  </joint>
  <link name="1link_r">
    <visual>
      <origin rpy="0 0 0" xyz="0 0 0"/>
      <geometry>
        <mesh filename="package://motoman_sia5d_support/meshes/sia5d/visual/link_r.dae"/>
      </geometry>
    </visual>
    <collision>
      <origin rpy="0 0 0" xyz="0 0 0"/>
      <geometry>
        <mesh filename="package://motoman_sia5d_support/meshes/sia5d/collision/link_r.dae"/>
      </geometry>
    </collision>
  </link>
  <joint name="1joint_r" type="revolute">
    <origin rpy="0 0 0" xyz="0.27 0 0.06"/>
    <parent link="1link_u"/>
    <child link="1link_r"/>
    <axis xyz="-1 0 0"/>
    <limit effort="0" lower="-1.57079637" upper="1.57079637" velocity="3.4906586"/>
  </joint>
  <link name="1link_b">
    <visual>
      <origin rpy="0 0 0" xyz="0 0 0"/>
      <geometry>
        <mesh filename="package://motoman_sia5d_support/meshes/sia5d/visual/link_b.dae"/>
      </geometry>
    </visual>
    <collision>
      <origin rpy="0 0 0" xyz="0 0 0"/>
      <geometry>
        <mesh filename="package://motoman_sia5d_support/meshes/sia5d/collision/link_b.dae"/>
      </geometry>
    </collision>
  </link>
  <joint name="1joint_b" type="revolute">
    <origin rpy="0 0 0" xyz="0 0 0"/>
    <parent link="1link_r"/>
    <child link="1link_b"/>
    <axis xyz="0 -1 0"/>
    <limit effort="0" lower="-1.91986223" upper="1.91986223" velocity="4.01425739"/>
  </joint>
  <link name="1link_t">
    <visual>
      <origin rpy="0 0 0" xyz="0 0 0"/>
      <geometry>
        <mesh filename="package://motoman_sia5d_support/meshes/sia5d/visual/link_t.dae"/>
      </geometry>
    </visual>
    <collision>
      <origin rpy="0 0 0" xyz="0 0 0"/>
      <geometry>
        <mesh filename="package://motoman_sia5d_support/meshes/sia5d/collision/link_t.dae"/>
      </geometry>
    </collision>
  </link>
  <joint name="1joint_t" type="revolute">
    <origin rpy="0 0 0" xyz="0.134 0 0"/>
    <parent link="1link_b"/>
    <child link="1link_t"/>
    <axis xyz="-1 0 0"/>
    <limit effort="0" lower="-1.57079637" upper="1.57079637" velocity="6.10865255"/>
  </joint>
  <link name="1tool0"/>
  <joint name="1link_t-tool0" type="fixed">
    <origin rpy="-1.57079637 -1.57079637 -1.57079637" xyz="0.011 0 0"/>
    <parent link="1link_t"/>
    <child link="1tool0"/>
  </joint>
  <!-- ROS base_link (via base_link) to Motoman Robot (not Base) Frame transform -->
  <link name="1base"/>
  <joint name="1base_link-base" type="fixed">
    <origin rpy="0 0 0" xyz="0 0 0.310"/>
    <parent link="1base_link"/>
    <child link="1base"/>
  </joint>
  <!--degrees to radians-->
  <link name="2base_link">
    <visual>
      <origin rpy="0 0 0" xyz="0 0 0"/>
      <geometry>
        <mesh filename="package://motoman_sia5d_support/meshes/sia5d/visual/base.dae"/>
      </geometry>
    </visual>
    <collision>
      <origin rpy="0 0 0" xyz="0 0 0"/>
      <geometry>
        <mesh filename="package://motoman_sia5d_support/meshes/sia5d/collision/base.dae"/>
      </geometry>
    </collision>
  </link>
  <link name="2link_s">
    <visual>
      <origin rpy="0 0 0" xyz="0 0 0"/>
      <geometry>
        <mesh filename="package://motoman_sia5d_support/meshes/sia5d/visual/link_s.dae"/>
      </geometry>
    </visual>
    <collision>
      <origin rpy="0 0 0" xyz="0 0 0"/>
      <geometry>
        <mesh filename="package://motoman_sia5d_support/meshes/sia5d/collision/link_s.dae"/>
      </geometry>
    </collision>
  </link>
  <joint name="2joint_s" type="revolute">
    <origin rpy="0 0 0" xyz="0 0 0.31"/>
    <!--r=${90*deg}-->
    <parent link="2base_link"/>
    <child link="2link_s"/>
    <axis xyz="0 0 1"/>
    <limit effort="0" lower="-3.14159274" upper="3.14159274" velocity="3.4906586"/>
  </joint>
  <link name="2link_l">
    <visual>
      <origin rpy="0 0 0" xyz="0 0 0"/>
      <geometry>
        <mesh filename="package://motoman_sia5d_support/meshes/sia5d/visual/link_l.dae"/>
      </geometry>
    </visual>
    <collision>
      <origin rpy="0 0 0" xyz="0 0 0"/>
      <geometry>
        <mesh filename="package://motoman_sia5d_support/meshes/sia5d/collision/link_l.dae"/>
      </geometry>
    </collision>
  </link>
  <joint name="2joint_l" type="revolute">
    <origin rpy="0 0 0" xyz="0 0 0"/>
    <parent link="2link_s"/>
    <child link="2link_l"/>
    <axis xyz="0 1 0"/>
    <limit effort="0" lower="-1.91986223" upper="1.91986223" velocity="3.4906586"/>
  </joint>
  <link name="2link_e">
    <visual>
      <origin rpy="0 0 0" xyz="0 0 0"/>
      <geometry>
        <mesh filename="package://motoman_sia5d_support/meshes/sia5d/visual/link_e.dae"/>
      </geometry>
    </visual>
    <collision>
      <origin rpy="0 0 0" xyz="0 0 0"/>
      <geometry>
        <mesh filename="package://motoman_sia5d_support/meshes/sia5d/collision/link_e.dae"/>
      </geometry>
    </collision>
  </link>
  <joint name="2joint_e" type="revolute">
    <origin rpy="0 0 0" xyz="0 0 0.27"/>
    <parent link="2link_l"/>
    <child link="2link_e"/>
    <axis xyz="0 0 1"/>
    <limit effort="0" lower="-2.96705981" upper="2.96705981" velocity="3.4906586"/>
  </joint>
  <link name="2link_u">
    <visual>
      <origin rpy="0 0 0" xyz="0 0 0"/>
      <geometry>
        <mesh filename="package://motoman_sia5d_support/meshes/sia5d/visual/link_u.dae"/>
      </geometry>
    </visual>
    <collision>
      <origin rpy="0 0 0" xyz="0 0 0"/>
      <geometry>
        <mesh filename="package://motoman_sia5d_support/meshes/sia5d/collision/link_u.dae"/>
      </geometry>
    </collision>
  </link>
  <joint name="2joint_u" type="revolute">
    <origin rpy="0 0 0" xyz="0.085 0 0"/>
    <parent link="2link_e"/>
    <child link="2link_u"/>
    <axis xyz="0 -1 0"/>
    <limit effort="0" lower="-1.57079637" upper="2.007128695" velocity="3.4906586"/>
  </joint>
  <link name="2link_r">
    <visual>
      <origin rpy="0 0 0" xyz="0 0 0"/>
      <geometry>
        <mesh filename="package://motoman_sia5d_support/meshes/sia5d/visual/link_r.dae"/>
      </geometry>
    </visual>
    <collision>
      <origin rpy="0 0 0" xyz="0 0 0"/>
      <geometry>
        <mesh filename="package://motoman_sia5d_support/meshes/sia5d/collision/link_r.dae"/>
      </geometry>
    </collision>
  </link>
  <joint name="2joint_r" type="revolute">
    <origin rpy="0 0 0" xyz="0.27 0 0.06"/>
    <parent link="2link_u"/>
    <child link="2link_r"/>
    <axis xyz="-1 0 0"/>
    <limit effort="0" lower="-1.57079637" upper="1.57079637" velocity="3.4906586"/>
  </joint>
  <link name="2link_b">
    <visual>
      <origin rpy="0 0 0" xyz="0 0 0"/>
      <geometry>
        <mesh filename="package://motoman_sia5d_support/meshes/sia5d/visual/link_b.dae"/>
      </geometry>
    </visual>
    <collision>
      <origin rpy="0 0 0" xyz="0 0 0"/>
      <geometry>
        <mesh filename="package://motoman_sia5d_support/meshes/sia5d/collision/link_b.dae"/>
      </geometry>
    </collision>
  </link>
  <joint name="2joint_b" type="revolute">
    <origin rpy="0 0 0" xyz="0 0 0"/>
    <parent link="2link_r"/>
    <child link="2link_b"/>
    <axis xyz="0 -1 0"/>
    <limit effort="0" lower="-1.91986223" upper="1.91986223" velocity="4.01425739"/>
  </joint>
  <link name="2link_t">
    <visual>
      <origin rpy="0 0 0" xyz="0 0 0"/>
      <geometry>
        <mesh filename="package://motoman_sia5d_support/meshes/sia5d/visual/link_t.dae"/>
      </geometry>
    </visual>
    <collision>
      <origin rpy="0 0 0" xyz="0 0 0"/>
      <geometry>
        <mesh filename="package://motoman_sia5d_support/meshes/sia5d/collision/link_t.dae"/>
      </geometry>
    </collision>
  </link>
  <joint name="2joint_t" type="revolute">
    <origin rpy="0 0 0" xyz="0.134 0 0"/>
    <parent link="2link_b"/>
    <child link="2link_t"/>
    <axis xyz="-1 0 0"/>
    <limit effort="0" lower="-1.57079637" upper="1.57079637" velocity="6.10865255"/>
  </joint>
  <link name="2tool0"/>
  <joint name="2link_t-tool0" type="fixed">
    <origin rpy="-1.57079637 -1.57079637 -1.57079637" xyz="0.011 0 0"/>
    <parent link="2link_t"/>
    <child link="2tool0"/>
  </joint>
  <!-- ROS base_link (via base_link) to Motoman Robot (not Base) Frame transform -->
  <link name="2base"/>
  <joint name="2base_link-base" type="fixed">
    <origin rpy="0 0 0" xyz="0 0 0.310"/>
    <parent link="2base_link"/>
    <child link="2base"/>
  </joint>
  <joint name="base_to_robot_1" type="fixed">
    <parent link="base_link"/>
    <child link="1base_link"/>
    <origin xyz="0 0.5 0.1"/>
  </joint>
  <joint name="base_to_robot_2" type="fixed">
    <parent link="base_link"/>
    <child link="2base_link"/>
    <origin xyz="0 -0.5 0.1"/>
  </joint>
</robot>

